<?xml version='1.0'?>
<sdf version='1.4'>
  <model name="my_robot">
<static>true</static>
<link name='chassis'>
            <pose>0 0 0 0 0 0</pose>

            <collision name='collision'>
              <geometry>
                <box>
                  <size>3 2 1</size>
                </box>
              </geometry>
            </collision>

          <visual name="visual">
          <pose>0 0 -0.155 0 0 0</pose>
        <geometry>
          <mesh>
            <uri>model://car_polo/meshes/Polo.dae</uri>
      	    <scale>0.04 0.04 0.04</scale>
          </mesh>
        </geometry>
      </visual>

	
</link>
<link name="left_wheel">
        <pose>1.6 3.5 0.25 1.5707 0 1.5707</pose>
        <collision name="collision">
          <geometry>
            <cylinder>
              <radius>.25</radius>
              <length>0.25</length>
            </cylinder>
          </geometry>
        </collision>
        <visual name="visual">
          <geometry>
            <cylinder>
              <radius>.25</radius>
              <length>0.25</length>
            </cylinder>
          </geometry>
        </visual>
      </link>
  <link name="right_wheel">
        <pose>1.7 0.8 0.25 1.5707 0 1.5707</pose>
        <collision name="collision">
          <geometry>
            <cylinder>
              <radius>.25</radius>
              <length>.25</length>
            </cylinder>
          </geometry>
        </collision>
        <visual name="visual">
          <geometry>
            <cylinder>
              <radius>.25</radius>
              <length>.25</length>
            </cylinder>
          </geometry>
        </visual>
      </link>
 <link name="front right wheel">
        <pose>0.3 3.4 0.25 1.5707 0 1.5707</pose>
        <collision name="collision">
          <geometry>
            <cylinder>
              <radius>.25</radius>
              <length>.25</length>
            </cylinder>
          </geometry>
        </collision>
        <visual name="visual">
          <geometry>
            <cylinder>
              <radius>.25</radius>
              <length>.25</length>
            </cylinder>
          </geometry>
        </visual>
      </link>
 <link name="front left wheel">
        <pose>0.3 0.9 0.25 1.5707 0 1.5707</pose>
        <collision name="collision">
          <geometry>
            <cylinder>
              <radius>.25</radius>
              <length>.25</length>
            </cylinder>
          </geometry>
        </collision>
        <visual name="visual">
          <geometry>
            <cylinder>
              <radius>.25</radius>
              <length>.25</length>
            </cylinder>
          </geometry>
        </visual>
      </link>
<joint type="revolute" name="left_wheel_hinge">
        <pose>0 0 -0.03 0 0 0</pose>
        <child>left_wheel</child>
        <parent>chassis</parent>
        <axis>
          <xyz>0 1 0</xyz>
        </axis>
      </joint>

      <joint type="revolute" name="right_wheel_hinge">
        <pose>0 0 0.03 0 0 0</pose>
        <child>right_wheel</child>
        <parent>chassis</parent>
        <axis>
          <xyz>0 1 0</xyz>
        </axis>
      </joint>
<joint type="revolute" name="front_left_wheel_hinge">
        <pose>0 0 -0.03 0 0 0</pose>
        <child>left_wheel</child>
        <parent>chassis</parent>
        <axis>
          <xyz>0 1 0</xyz>
        </axis>
      </joint>

      <joint type="revolute" name="front_right_wheel_hinge">
        <pose>0 0 0.03 0 0 0</pose>
        <child>right_wheel</child>
        <parent>chassis</parent>
        <axis>
          <xyz>0 1 0</xyz>
        </axis>
      </joint>

	
	
  </model>
</sdf>
